2019-12-26 23:34:22,823 ERROR: Exception on /dashboard [GET] [in c:\users\samuel\desktop\pydasci\venv\lib\site-packages\flask\app.py:1891]
Traceback (most recent call last):
  File "c:\users\samuel\desktop\pydasci\venv\lib\site-packages\flask\app.py", line 2446, in wsgi_app
    response = self.full_dispatch_request()
  File "c:\users\samuel\desktop\pydasci\venv\lib\site-packages\flask\app.py", line 1951, in full_dispatch_request
    rv = self.handle_user_exception(e)
  File "c:\users\samuel\desktop\pydasci\venv\lib\site-packages\flask\app.py", line 1820, in handle_user_exception
    reraise(exc_type, exc_value, tb)
  File "c:\users\samuel\desktop\pydasci\venv\lib\site-packages\flask\app.py", line 1949, in full_dispatch_request
    rv = self.dispatch_request()
  File "c:\users\samuel\desktop\pydasci\venv\lib\site-packages\flask\app.py", line 1935, in dispatch_request
    return self.view_functions[rule.endpoint](**req.view_args)
  File "c:\users\samuel\desktop\pydasci\venv\lib\site-packages\flask_login\utils.py", line 261, in decorated_view
    return func(*args, **kwargs)
  File "C:\Users\Samuel\Desktop\pydasci\app\dashboard\routes.py", line 15, in dashboard
    if articles.id>0:
AttributeError: 'list' object has no attribute 'id'
2019-12-26 23:36:02,418 ERROR: Exception on /dashboard [GET] [in c:\users\samuel\desktop\pydasci\venv\lib\site-packages\flask\app.py:1891]
Traceback (most recent call last):
  File "c:\users\samuel\desktop\pydasci\venv\lib\site-packages\flask\app.py", line 2446, in wsgi_app
    response = self.full_dispatch_request()
  File "c:\users\samuel\desktop\pydasci\venv\lib\site-packages\flask\app.py", line 1951, in full_dispatch_request
    rv = self.handle_user_exception(e)
  File "c:\users\samuel\desktop\pydasci\venv\lib\site-packages\flask\app.py", line 1820, in handle_user_exception
    reraise(exc_type, exc_value, tb)
  File "c:\users\samuel\desktop\pydasci\venv\lib\site-packages\flask\app.py", line 1949, in full_dispatch_request
    rv = self.dispatch_request()
  File "c:\users\samuel\desktop\pydasci\venv\lib\site-packages\flask\app.py", line 1935, in dispatch_request
    return self.view_functions[rule.endpoint](**req.view_args)
  File "c:\users\samuel\desktop\pydasci\venv\lib\site-packages\flask_login\utils.py", line 261, in decorated_view
    return func(*args, **kwargs)
  File "C:\Users\Samuel\Desktop\pydasci\app\dashboard\routes.py", line 15, in dashboard
    if articles['id']>0:
AttributeError: 'list' object has no attribute 'id'
2019-12-26 23:36:04,651 ERROR: Exception on /dashboard [GET] [in c:\users\samuel\desktop\pydasci\venv\lib\site-packages\flask\app.py:1891]
Traceback (most recent call last):
  File "c:\users\samuel\desktop\pydasci\venv\lib\site-packages\flask\app.py", line 2446, in wsgi_app
    response = self.full_dispatch_request()
  File "c:\users\samuel\desktop\pydasci\venv\lib\site-packages\flask\app.py", line 1951, in full_dispatch_request
    rv = self.handle_user_exception(e)
  File "c:\users\samuel\desktop\pydasci\venv\lib\site-packages\flask\app.py", line 1820, in handle_user_exception
    reraise(exc_type, exc_value, tb)
  File "c:\users\samuel\desktop\pydasci\venv\lib\site-packages\flask\app.py", line 1949, in full_dispatch_request
    rv = self.dispatch_request()
  File "c:\users\samuel\desktop\pydasci\venv\lib\site-packages\flask\app.py", line 1935, in dispatch_request
    return self.view_functions[rule.endpoint](**req.view_args)
  File "c:\users\samuel\desktop\pydasci\venv\lib\site-packages\flask_login\utils.py", line 261, in decorated_view
    return func(*args, **kwargs)
  File "C:\Users\Samuel\Desktop\pydasci\app\dashboard\routes.py", line 15, in dashboard
    if articles['id']>0:
AttributeError: 'list' object has no attribute 'id'
2019-12-26 23:36:36,727 ERROR: Exception on /article [POST] [in c:\users\samuel\desktop\pydasci\venv\lib\site-packages\flask\app.py:1891]
Traceback (most recent call last):
  File "c:\users\samuel\desktop\pydasci\venv\lib\site-packages\flask\app.py", line 2446, in wsgi_app
    response = self.full_dispatch_request()
  File "c:\users\samuel\desktop\pydasci\venv\lib\site-packages\flask\app.py", line 1951, in full_dispatch_request
    rv = self.handle_user_exception(e)
  File "c:\users\samuel\desktop\pydasci\venv\lib\site-packages\flask\app.py", line 1820, in handle_user_exception
    reraise(exc_type, exc_value, tb)
  File "c:\users\samuel\desktop\pydasci\venv\lib\site-packages\flask\app.py", line 1949, in full_dispatch_request
    rv = self.dispatch_request()
  File "c:\users\samuel\desktop\pydasci\venv\lib\site-packages\flask\app.py", line 1935, in dispatch_request
    return self.view_functions[rule.endpoint](**req.view_args)
  File "c:\users\samuel\desktop\pydasci\venv\lib\site-packages\flask_login\utils.py", line 261, in decorated_view
    return func(*args, **kwargs)
  File "C:\Users\Samuel\Desktop\pydasci\app\articles\routes.py", line 18, in article
    db.session.commit()
  File "c:\users\samuel\desktop\pydasci\venv\lib\site-packages\sqlalchemy\orm\scoping.py", line 162, in do
    return getattr(self.registry(), name)(*args, **kwargs)
  File "c:\users\samuel\desktop\pydasci\venv\lib\site-packages\sqlalchemy\orm\session.py", line 1036, in commit
    self.transaction.commit()
  File "c:\users\samuel\desktop\pydasci\venv\lib\site-packages\sqlalchemy\orm\session.py", line 503, in commit
    self._prepare_impl()
  File "c:\users\samuel\desktop\pydasci\venv\lib\site-packages\sqlalchemy\orm\session.py", line 482, in _prepare_impl
    self.session.flush()
  File "c:\users\samuel\desktop\pydasci\venv\lib\site-packages\sqlalchemy\orm\session.py", line 2479, in flush
    self._flush(objects)
  File "c:\users\samuel\desktop\pydasci\venv\lib\site-packages\sqlalchemy\orm\session.py", line 2617, in _flush
    transaction.rollback(_capture_exception=True)
  File "c:\users\samuel\desktop\pydasci\venv\lib\site-packages\sqlalchemy\util\langhelpers.py", line 68, in __exit__
    compat.reraise(exc_type, exc_value, exc_tb)
  File "c:\users\samuel\desktop\pydasci\venv\lib\site-packages\sqlalchemy\orm\session.py", line 2577, in _flush
    flush_context.execute()
  File "c:\users\samuel\desktop\pydasci\venv\lib\site-packages\sqlalchemy\orm\unitofwork.py", line 422, in execute
    rec.execute(self)
  File "c:\users\samuel\desktop\pydasci\venv\lib\site-packages\sqlalchemy\orm\unitofwork.py", line 589, in execute
    uow,
  File "c:\users\samuel\desktop\pydasci\venv\lib\site-packages\sqlalchemy\orm\persistence.py", line 245, in save_obj
    insert,
  File "c:\users\samuel\desktop\pydasci\venv\lib\site-packages\sqlalchemy\orm\persistence.py", line 1137, in _emit_insert_statements
    statement, params
  File "c:\users\samuel\desktop\pydasci\venv\lib\site-packages\sqlalchemy\engine\base.py", line 982, in execute
    return meth(self, multiparams, params)
  File "c:\users\samuel\desktop\pydasci\venv\lib\site-packages\sqlalchemy\sql\elements.py", line 287, in _execute_on_connection
    return connection._execute_clauseelement(self, multiparams, params)
  File "c:\users\samuel\desktop\pydasci\venv\lib\site-packages\sqlalchemy\engine\base.py", line 1101, in _execute_clauseelement
    distilled_params,
  File "c:\users\samuel\desktop\pydasci\venv\lib\site-packages\sqlalchemy\engine\base.py", line 1250, in _execute_context
    e, statement, parameters, cursor, context
  File "c:\users\samuel\desktop\pydasci\venv\lib\site-packages\sqlalchemy\engine\base.py", line 1476, in _handle_dbapi_exception
    util.raise_from_cause(sqlalchemy_exception, exc_info)
  File "c:\users\samuel\desktop\pydasci\venv\lib\site-packages\sqlalchemy\util\compat.py", line 398, in raise_from_cause
    reraise(type(exception), exception, tb=exc_tb, cause=cause)
  File "c:\users\samuel\desktop\pydasci\venv\lib\site-packages\sqlalchemy\engine\base.py", line 1246, in _execute_context
    cursor, statement, parameters, context
  File "c:\users\samuel\desktop\pydasci\venv\lib\site-packages\sqlalchemy\engine\default.py", line 581, in do_execute
    cursor.execute(statement, parameters)
IntegrityError: (sqlite3.IntegrityError) UNIQUE constraint failed: article.text3
[SQL: INSERT INTO article (title, text1, text2, text3, date_created) VALUES (?, ?, ?, ?, ?)]
[parameters: (u'Glucose and energy', u"Lorem Ipsum is simply dummy text of the printing and typesetting industry. Lorem Ipsum has been the industry's standard dummy text ever since the 15 ... (276 characters truncated) ... set sheets containing Lorem Ipsum passages, and more recently with desktop publishing software like Aldus PageMaker including versions of Lorem Ipsum", u"Lorem Ipsum is simply dummy text of the printing and typesetting industry. Lorem Ipsum has been the industry's standard dummy text ever since the 15 ... (276 characters truncated) ... set sheets containing Lorem Ipsum passages, and more recently with desktop publishing software like Aldus PageMaker including versions of Lorem Ipsum", u"Lorem Ipsum is simply dummy text of the printing and typesetting industry. Lorem Ipsum has been the industry's standard dummy text ever since the 15 ... (276 characters truncated) ... set sheets containing Lorem Ipsum passages, and more recently with desktop publishing software like Aldus PageMaker including versions of Lorem Ipsum", '2019-12-26 21:36:36.728000')]
(Background on this error at: http://sqlalche.me/e/gkpj)
2019-12-26 23:38:51,362 INFO: Microblog startup [in C:\Users\Samuel\Desktop\pydasci\app\__init__.py:79]
2019-12-26 23:38:57,312 INFO: Microblog startup [in C:\Users\Samuel\Desktop\pydasci\app\__init__.py:79]
2019-12-26 23:39:08,880 INFO: Microblog startup [in C:\Users\Samuel\Desktop\pydasci\app\__init__.py:79]
2019-12-26 23:43:00,058 INFO: Microblog startup [in app\__init__.py:79]
2019-12-26 23:43:09,170 INFO: Microblog startup [in app\__init__.py:79]
2019-12-26 23:43:09,170 INFO: Microblog startup [in app\__init__.py:79]
2019-12-26 23:50:40,355 INFO: Microblog startup [in C:\Users\Samuel\Desktop\pydasci\app\__init__.py:79]
2019-12-26 23:51:07,410 INFO: Microblog startup [in C:\Users\Samuel\Desktop\pydasci\app\__init__.py:79]
