2019-12-26 22:09:45,128 ERROR: Exception on / [GET] [in c:\users\samuel\desktop\pydasci\venv\lib\site-packages\flask\app.py:1891]
Traceback (most recent call last):
  File "c:\users\samuel\desktop\pydasci\venv\lib\site-packages\flask\app.py", line 2446, in wsgi_app
    response = self.full_dispatch_request()
  File "c:\users\samuel\desktop\pydasci\venv\lib\site-packages\flask\app.py", line 1951, in full_dispatch_request
    rv = self.handle_user_exception(e)
  File "c:\users\samuel\desktop\pydasci\venv\lib\site-packages\flask\app.py", line 1820, in handle_user_exception
    reraise(exc_type, exc_value, tb)
  File "c:\users\samuel\desktop\pydasci\venv\lib\site-packages\flask\app.py", line 1949, in full_dispatch_request
    rv = self.dispatch_request()
  File "c:\users\samuel\desktop\pydasci\venv\lib\site-packages\flask\app.py", line 1935, in dispatch_request
    return self.view_functions[rule.endpoint](**req.view_args)
  File "C:\Users\Samuel\Desktop\pydasci\app\main\routes.py", line 30, in index
    return render_template('index.html', title=('Home'))
  File "c:\users\samuel\desktop\pydasci\venv\lib\site-packages\flask\templating.py", line 140, in render_template
    ctx.app,
  File "c:\users\samuel\desktop\pydasci\venv\lib\site-packages\flask\templating.py", line 120, in _render
    rv = template.render(context)
  File "c:\users\samuel\desktop\pydasci\venv\lib\site-packages\jinja2\environment.py", line 1008, in render
    return self.environment.handle_exception(exc_info, True)
  File "c:\users\samuel\desktop\pydasci\venv\lib\site-packages\jinja2\environment.py", line 780, in handle_exception
    reraise(exc_type, exc_value, tb)
  File "C:\Users\Samuel\Desktop\pydasci\app\templates\index.html", line 4, in top-level template code
    {% import 'bootstrap/wtf.html' as wtf %}
  File "C:\Users\Samuel\Desktop\pydasci\app\templates\base.html", line 37, in top-level template code
    <a class="nav-link" href="{{url_for('dashboard.article')}}">Dashboard-Articles</a>
  File "c:\users\samuel\desktop\pydasci\venv\lib\site-packages\flask\helpers.py", line 370, in url_for
    return appctx.app.handle_url_build_error(error, endpoint, values)
  File "c:\users\samuel\desktop\pydasci\venv\lib\site-packages\flask\app.py", line 2215, in handle_url_build_error
    reraise(exc_type, exc_value, tb)
  File "c:\users\samuel\desktop\pydasci\venv\lib\site-packages\flask\helpers.py", line 358, in url_for
    endpoint, values, method=method, force_external=external
  File "c:\users\samuel\desktop\pydasci\venv\lib\site-packages\werkzeug\routing.py", line 2020, in build
    raise BuildError(endpoint, values, method, self)
BuildError: Could not build url for endpoint 'dashboard.article'. Did you mean 'dashboard.dashboard' instead?
2019-12-26 22:11:20,308 INFO: Microblog startup [in C:\Users\Samuel\Desktop\pydasci\app\__init__.py:79]
2019-12-26 22:11:41,007 ERROR: Exception on /dashboard [GET] [in c:\users\samuel\desktop\pydasci\venv\lib\site-packages\flask\app.py:1891]
Traceback (most recent call last):
  File "c:\users\samuel\desktop\pydasci\venv\lib\site-packages\flask\app.py", line 2446, in wsgi_app
    response = self.full_dispatch_request()
  File "c:\users\samuel\desktop\pydasci\venv\lib\site-packages\flask\app.py", line 1952, in full_dispatch_request
    return self.finalize_request(rv)
  File "c:\users\samuel\desktop\pydasci\venv\lib\site-packages\flask\app.py", line 1967, in finalize_request
    response = self.make_response(rv)
  File "c:\users\samuel\desktop\pydasci\venv\lib\site-packages\flask\app.py", line 2097, in make_response
    "The view function did not return a valid response. The"
TypeError: The view function did not return a valid response. The function either returned None or ended without a return statement.
2019-12-26 22:12:17,082 ERROR: Exception on /dashboard [GET] [in c:\users\samuel\desktop\pydasci\venv\lib\site-packages\flask\app.py:1891]
Traceback (most recent call last):
  File "c:\users\samuel\desktop\pydasci\venv\lib\site-packages\flask\app.py", line 2446, in wsgi_app
    response = self.full_dispatch_request()
  File "c:\users\samuel\desktop\pydasci\venv\lib\site-packages\flask\app.py", line 1952, in full_dispatch_request
    return self.finalize_request(rv)
  File "c:\users\samuel\desktop\pydasci\venv\lib\site-packages\flask\app.py", line 1967, in finalize_request
    response = self.make_response(rv)
  File "c:\users\samuel\desktop\pydasci\venv\lib\site-packages\flask\app.py", line 2097, in make_response
    "The view function did not return a valid response. The"
TypeError: The view function did not return a valid response. The function either returned None or ended without a return statement.
2019-12-26 22:12:18,503 ERROR: Exception on /dashboard [GET] [in c:\users\samuel\desktop\pydasci\venv\lib\site-packages\flask\app.py:1891]
Traceback (most recent call last):
  File "c:\users\samuel\desktop\pydasci\venv\lib\site-packages\flask\app.py", line 2446, in wsgi_app
    response = self.full_dispatch_request()
  File "c:\users\samuel\desktop\pydasci\venv\lib\site-packages\flask\app.py", line 1952, in full_dispatch_request
    return self.finalize_request(rv)
  File "c:\users\samuel\desktop\pydasci\venv\lib\site-packages\flask\app.py", line 1967, in finalize_request
    response = self.make_response(rv)
  File "c:\users\samuel\desktop\pydasci\venv\lib\site-packages\flask\app.py", line 2097, in make_response
    "The view function did not return a valid response. The"
TypeError: The view function did not return a valid response. The function either returned None or ended without a return statement.
2019-12-26 22:15:42,464 INFO: Microblog startup [in C:\Users\Samuel\Desktop\pydasci\app\__init__.py:79]
2019-12-26 22:21:32,240 INFO: Microblog startup [in C:\Users\Samuel\Desktop\pydasci\app\__init__.py:79]
2019-12-26 22:24:07,256 INFO: Microblog startup [in C:\Users\Samuel\Desktop\pydasci\app\__init__.py:79]
2019-12-26 22:24:40,596 ERROR: Exception on /dashboard [GET] [in c:\users\samuel\desktop\pydasci\venv\lib\site-packages\flask\app.py:1891]
Traceback (most recent call last):
  File "c:\users\samuel\desktop\pydasci\venv\lib\site-packages\flask\app.py", line 2446, in wsgi_app
    response = self.full_dispatch_request()
  File "c:\users\samuel\desktop\pydasci\venv\lib\site-packages\flask\app.py", line 1952, in full_dispatch_request
    return self.finalize_request(rv)
  File "c:\users\samuel\desktop\pydasci\venv\lib\site-packages\flask\app.py", line 1967, in finalize_request
    response = self.make_response(rv)
  File "c:\users\samuel\desktop\pydasci\venv\lib\site-packages\flask\app.py", line 2097, in make_response
    "The view function did not return a valid response. The"
TypeError: The view function did not return a valid response. The function either returned None or ended without a return statement.
2019-12-26 22:42:19,180 INFO: Microblog startup [in C:\Users\Samuel\Desktop\pydasci\app\__init__.py:79]
2019-12-26 22:42:27,467 ERROR: Exception on /dashboard [GET] [in c:\users\samuel\desktop\pydasci\venv\lib\site-packages\flask\app.py:1891]
Traceback (most recent call last):
  File "c:\users\samuel\desktop\pydasci\venv\lib\site-packages\flask\app.py", line 2446, in wsgi_app
    response = self.full_dispatch_request()
  File "c:\users\samuel\desktop\pydasci\venv\lib\site-packages\flask\app.py", line 1951, in full_dispatch_request
    rv = self.handle_user_exception(e)
  File "c:\users\samuel\desktop\pydasci\venv\lib\site-packages\flask\app.py", line 1820, in handle_user_exception
    reraise(exc_type, exc_value, tb)
  File "c:\users\samuel\desktop\pydasci\venv\lib\site-packages\flask\app.py", line 1949, in full_dispatch_request
    rv = self.dispatch_request()
  File "c:\users\samuel\desktop\pydasci\venv\lib\site-packages\flask\app.py", line 1935, in dispatch_request
    return self.view_functions[rule.endpoint](**req.view_args)
  File "c:\users\samuel\desktop\pydasci\venv\lib\site-packages\flask_login\utils.py", line 261, in decorated_view
    return func(*args, **kwargs)
  File "C:\Users\Samuel\Desktop\pydasci\app\dashboard\routes.py", line 14, in dashboard
    form=ArticleForm
NameError: global name 'ArticleForm' is not defined
2019-12-26 22:42:51,523 INFO: Microblog startup [in C:\Users\Samuel\Desktop\pydasci\app\__init__.py:79]
