2019-12-27 00:26:13,927 ERROR: Exception on /dashboard [GET] [in c:\users\samuel\desktop\pydasci\venv\lib\site-packages\flask\app.py:1891]
Traceback (most recent call last):
  File "c:\users\samuel\desktop\pydasci\venv\lib\site-packages\flask\app.py", line 2446, in wsgi_app
    response = self.full_dispatch_request()
  File "c:\users\samuel\desktop\pydasci\venv\lib\site-packages\flask\app.py", line 1951, in full_dispatch_request
    rv = self.handle_user_exception(e)
  File "c:\users\samuel\desktop\pydasci\venv\lib\site-packages\flask\app.py", line 1820, in handle_user_exception
    reraise(exc_type, exc_value, tb)
  File "c:\users\samuel\desktop\pydasci\venv\lib\site-packages\flask\app.py", line 1949, in full_dispatch_request
    rv = self.dispatch_request()
  File "c:\users\samuel\desktop\pydasci\venv\lib\site-packages\flask\app.py", line 1935, in dispatch_request
    return self.view_functions[rule.endpoint](**req.view_args)
  File "c:\users\samuel\desktop\pydasci\venv\lib\site-packages\flask_login\utils.py", line 261, in decorated_view
    return func(*args, **kwargs)
  File "C:\Users\Samuel\Desktop\pydasci\app\dashboard\routes.py", line 16, in dashboard
    return render_template('dashbaord/articles.html',articles=articles,title='Articles')
  File "c:\users\samuel\desktop\pydasci\venv\lib\site-packages\flask\templating.py", line 138, in render_template
    ctx.app.jinja_env.get_or_select_template(template_name_or_list),
  File "c:\users\samuel\desktop\pydasci\venv\lib\site-packages\jinja2\environment.py", line 869, in get_or_select_template
    return self.get_template(template_name_or_list, parent, globals)
  File "c:\users\samuel\desktop\pydasci\venv\lib\site-packages\jinja2\environment.py", line 830, in get_template
    return self._load_template(name, self.make_globals(globals))
  File "c:\users\samuel\desktop\pydasci\venv\lib\site-packages\jinja2\environment.py", line 804, in _load_template
    template = self.loader.load(self, name, globals)
  File "c:\users\samuel\desktop\pydasci\venv\lib\site-packages\jinja2\loaders.py", line 113, in load
    source, filename, uptodate = self.get_source(environment, name)
  File "c:\users\samuel\desktop\pydasci\venv\lib\site-packages\flask\templating.py", line 60, in get_source
    return self._get_source_fast(environment, template)
  File "c:\users\samuel\desktop\pydasci\venv\lib\site-packages\flask\templating.py", line 89, in _get_source_fast
    raise TemplateNotFound(template)
TemplateNotFound: dashbaord/articles.html
2019-12-27 00:26:41,565 INFO: Microblog startup [in C:\Users\Samuel\Desktop\pydasci\app\__init__.py:79]
2019-12-27 00:26:58,259 ERROR: Exception on /dashboard [GET] [in c:\users\samuel\desktop\pydasci\venv\lib\site-packages\flask\app.py:1891]
Traceback (most recent call last):
  File "c:\users\samuel\desktop\pydasci\venv\lib\site-packages\flask\app.py", line 2446, in wsgi_app
    response = self.full_dispatch_request()
  File "c:\users\samuel\desktop\pydasci\venv\lib\site-packages\flask\app.py", line 1951, in full_dispatch_request
    rv = self.handle_user_exception(e)
  File "c:\users\samuel\desktop\pydasci\venv\lib\site-packages\flask\app.py", line 1820, in handle_user_exception
    reraise(exc_type, exc_value, tb)
  File "c:\users\samuel\desktop\pydasci\venv\lib\site-packages\flask\app.py", line 1949, in full_dispatch_request
    rv = self.dispatch_request()
  File "c:\users\samuel\desktop\pydasci\venv\lib\site-packages\flask\app.py", line 1935, in dispatch_request
    return self.view_functions[rule.endpoint](**req.view_args)
  File "c:\users\samuel\desktop\pydasci\venv\lib\site-packages\flask_login\utils.py", line 261, in decorated_view
    return func(*args, **kwargs)
  File "C:\Users\Samuel\Desktop\pydasci\app\dashboard\routes.py", line 16, in dashboard
    return render_template('dashboard/articles.html',articles=articles,title='Articles')
  File "c:\users\samuel\desktop\pydasci\venv\lib\site-packages\flask\templating.py", line 138, in render_template
    ctx.app.jinja_env.get_or_select_template(template_name_or_list),
  File "c:\users\samuel\desktop\pydasci\venv\lib\site-packages\jinja2\environment.py", line 869, in get_or_select_template
    return self.get_template(template_name_or_list, parent, globals)
  File "c:\users\samuel\desktop\pydasci\venv\lib\site-packages\jinja2\environment.py", line 830, in get_template
    return self._load_template(name, self.make_globals(globals))
  File "c:\users\samuel\desktop\pydasci\venv\lib\site-packages\jinja2\environment.py", line 804, in _load_template
    template = self.loader.load(self, name, globals)
  File "c:\users\samuel\desktop\pydasci\venv\lib\site-packages\jinja2\loaders.py", line 125, in load
    code = environment.compile(source, name, filename)
  File "c:\users\samuel\desktop\pydasci\venv\lib\site-packages\jinja2\environment.py", line 591, in compile
    self.handle_exception(exc_info, source_hint=source_hint)
  File "c:\users\samuel\desktop\pydasci\venv\lib\site-packages\jinja2\environment.py", line 780, in handle_exception
    reraise(exc_type, exc_value, tb)
  File "C:\Users\Samuel\Desktop\pydasci\app\templates\dashboard\articles.html", line 26, in template
    {% endblock%}
TemplateSyntaxError: Encountered unknown tag 'endblock'. You probably made a nesting mistake. Jinja is expecting this tag, but currently looking for 'endfor' or 'else'. The innermost block that needs to be closed is 'for'.
2019-12-27 00:27:51,446 INFO: Microblog startup [in C:\Users\Samuel\Desktop\pydasci\app\__init__.py:79]
2019-12-27 00:31:54,480 INFO: Microblog startup [in C:\Users\Samuel\Desktop\pydasci\app\__init__.py:79]
2019-12-28 18:32:18,408 INFO: Microblog startup [in C:\Users\Samuel\Desktop\pydasci\app\__init__.py:79]
